Workbook

Sheet แคตตาล็อกผลงาน
A1: แคตตาล็อกผลงานที่สร้างด้วย AI
A2: รวบรวมจากคอมเมนต์ในโพสต์ Facebook · 147 ผลงาน · 16 หมวดหมู่
A3: ที่มาของโพสต์
A5: ลำดับ | B5: หมวดหมู่ | C5: ชื่อผลงาน | D5: รายละเอียด | E5: ผู้สร้าง | F5: ลิงก์ผลงาน | G5: ลิงก์เพิ่มเติม | H5: ยอดรีแอ็กชัน | I5: สถานะลิงก์ | J5: คอมเมนต์ต้นทาง
A6: 1 | B6: การเงิน & บัญชี | C6: Planndee | D6: เว็บวางแผนเกษียณและภาษี สร้างจาก pain point ของผู้พัฒนาเอง เปิดให้ทดลองใช้และส่ง feedback ได้ | E6: Seymour Guado | F6: https://planndee.com/ | G6: https://www.facebook.com/share/1JEAuXjV6F/ | H6: 728 | I6: ใช้ได้ | J6: เปิดคอมเมนต์
A7: 2 | B7: การเงิน & บัญชี | C7: Vaulta Family Office | D7: แอปจัดการสินทรัพย์ครอบครัวในที่เดียว บันทึกทรัพย์สิน เอกสารสำคัญ และความทรงจำ พร้อมกำหนดสัดส่วนมรดกผ่านแผนภาพ | E7: EarthDeFIRE | F7: https://vaulta.family/ | G7: https://www.facebook.com/EarthDeFIRE/posts/pfbid0vCFBsHZBj4JwVRrFngHPXy8rKJ6w77a4vY6qoCxbh7gGsVNw5cpECnssJrsYuqakl | H7: 268 | I7: ใช้ได้ | J7: เปิดคอมเมนต์
A8: 3 | B8: การเงิน & บัญชี | C8: DooSpend | D8: แอปบันทึกรายรับรายจ่ายสำหรับคนขี้เกียจจด เจ้าของระบุว่าใช้ Claude Code 98% ปรับ UI เอง 2% | E8: Apiwat Pengjam | F8: https://apps.apple.com/app/id6774424817 | H8: 39 | I8: ใช้ได้ | J8: เปิดคอมเมนต์
A9: 4 | B9: การเงิน & บัญชี | C9: ระบบจัดการการเงินส่วนบุคคล (Saruth Volk) | D9: เว็บ + LINE bot จัดการเงินส่วนบุคคล ลงทุน วางแผน จดรายรับรายจ่าย และดู DCA ใช้ได้ทั้ง desktop และมือถือ | E9: Saruth Volk | F9: https://lin.ee/YmHMOAja | G9: https://www.facebook.com/share/p/17subazubt/ https://www.facebook.com/share/p/1Eu4RpJjfH/ | H9: 36 | I9: ใช้ได้ | J9: เปิดคอมเมนต์
A10: 5 | B10: การเงิน & บัญชี | C10: แอปจดรายรับรายจ่าย (Trancient Circuit) | D10: แอปจดรายรับรายจ่ายขนาดเล็กบน Android | E10: Trancient Circuit | F10: https://play.google.com/store/apps/details | H10: 22 | I10: ลิงก์ถูก Facebook ตัด — ต้องค้นหาเอง | J10: เปิดคอมเมนต์
A11: 6 | B11: การเงิน & บัญชี | C11: Skill วิเคราะห์หุ้นและกองทุน REIT | D11: Claude Skill ช่วยวิเคราะห์ประเมินราคาหุ้นและกองทุน REIT เปิดให้โหลดฟรี | E11: Chapter | F11: https://www.facebook.com/share/14oaY7JYB5Z/ | H11: 15 | I11: ใช้ได้ | J11: เปิดคอมเมนต์
A12: 7 | B12: การเงิน & บัญชี | C12: ประกันง่าย (PraganEasy) | D12: เว็บเปรียบเทียบและซื้อประกัน | E12: Pui Poompui | F12: https://www.praganeasy.com/ | H12: 10 | I12: ใช้ได้ | J12: เปิดคอมเมนต์
A13: 8 | B13: การเงิน & บัญชี | C13: OpenLedger CFO | D13: AI ที่ปรึกษาการเงินส่วนตัวแบบ Terminal + AI agent รันบน local เพื่อรักษาความเป็นส่วนตัว เปิด open source | E13: Phureewat Aphibansri | F13: https://github.com/phureewat29/openledger-cfo | G13: https://openledger.sh | H13: 6 | I13: ใช้ได้ | J13: เปิดคอมเมนต์
A14: 9 | B14: การเงิน & บัญชี | C14: ตังใจ (Tangjai) | D14: บันทึกรายรับ-รายจ่ายผ่าน LINE + LIFF มี Dashboard และ OCR อ่านสลิป สร้างด้วย Claude + Codex | E14: Patradanai Nakpimai | F14: https://www.tangjai.online | H14: 4 | I14: ใช้ได้ | J14: เปิดคอมเมนต์
A15: 10 | B15: การเงิน & บัญชี | C15: ใบไหนดี (BaiNaiDee) | D15: เว็บ + chatbot ช่วยหาโปรโมชั่นบัตรเครดิตข้ามค่าย และเปรียบเทียบบัตรตอนสมัคร | E15: Fluke Narathat | F15: https://bainaidee.com/ | H15: 4 | I15: ใช้ได้ | J15: เปิดคอมเมนต์
A16: 11 | B16: การเงิน & บัญชี | C16: Birney | D16: แอปบันทึกรายรับรายจ่ายที่สร้างด้วย Claude และให้ Claude นำขึ้น App Store ให้ | E16: Pakphum Benjadechachai | F16: https://apps.apple.com/th/app/birney/id6764335697 | H16: 2 | I16: ใช้ได้ | J16: เปิดคอมเมนต์
A17: 12 | B17: การเงิน & บัญชี | C17: Budgy | D17: แอปบันทึกรายรับรายจ่าย สแกนสลิป import statement บัตรเครดิต และกำลังเพิ่มฟีเจอร์แชร์บิลกับเพื่อน | E17: Kwang Theeraporn | F17: https://budgy.life | H17: 2 | I17: ใช้ได้ | J17: เปิดคอมเมนต์
A18: 13 | B18: การเงิน & บัญชี | C18: PocketBird | D18: แอปบันทึกรายรับรายจ่ายที่เน้นจัดการหนี้สินและวางแผนการเงิน (เฉพาะ iOS) | E18: Nattapong Pallawal | F18: https://pocketbirdapp.com | H18: 2 | I18: ใช้ได้ | J18: เปิดคอมเมนต์
A19: 14 | B19: การเงิน & บัญชี | C19: Your Money 2026 | D19: เว็บแอปจัดการเงินส่วนบุคคล ตั้งรหัส PIN แล้วใช้งานได้ทันที เพิ่มไว้หน้าโฮมได้ | E19: Parichat Salee | F19: https://your-money2026.tothemoon-gts2026.workers.dev/ | H19: 0 | I19: ใช้ได้ | J19: เปิดคอมเมนต์
A20: 15 | B20: ธุรกิจ ร้านค้า & ระบบองค์กร | C20: Meysure | D20: โปรแกรมถอดแบบก่อสร้าง (QS) พัฒนาราว 2 สัปดาห์ 700 commits | E20: Sirawit Mahanin | F20: https://meysure.com/ | G20: https://app.meysure.com/ | H20: 296 | I20: ใช้ได้ | J20: เปิดคอมเมนต์
A21: 16 | B21: ธุรกิจ ร้านค้า & ระบบองค์กร | C21: RoostFarm | D21: ระบบบริหารจัดการฟาร์มไก่ มอนิเตอร์ฟาร์ม จัดการอะไหล่ บันทึกงานประจำวัน และแจ้งเตือนผ่าน LINE | E21: Boonyasit Thanapasavat | F21: https://roostfarm.vercel.app | H21: 48 | I21: ใช้ได้ | J21: เปิดคอมเมนต์
A22: 17 | B22: ธุรกิจ ร้านค้า & ระบบองค์กร | C22: Do-Ngan | D22: ระบบติดตามงาน ดูภาพรวมว่าใครในบริษัทมีงานอะไรและทำถึงไหน | E22: Apichart Khemawatcharayothin | F22: https://do-ngan.com/ | H22: 41 | I22: ใช้ได้ | J22: เปิดคอมเมนต์
A23: 18 | B23: ธุรกิจ ร้านค้า & ระบบองค์กร | C23: CafeMates | D23: แอปบริหารคาเฟ่และร้านอาหาร จัดเวรจัดกะ สต๊อกของสด การจัดตู้ขนม ระบบลา และแจ้งเหตุการณ์ | E23: KuangGy Kulchotirat | F23: https://www.cafemates.app/ | H23: 13 | I23: ใช้ได้ | J23: เปิดคอมเมนต์
A24: 19 | B24: ธุรกิจ ร้านค้า & ระบบองค์กร | C24: SaaS Thai | D24: ระบบที่ใช้งานจริงอยู่ เปิดให้ผู้อื่นมาร่วมได้ (เจ้าของไม่ได้ระบุรายละเอียด) | E24: Arkom Rattanasiri | F24: https://saasthai.com | H24: 13 | I24: ใช้ได้ | J24: เปิดคอมเมนต์
A25: 20 | B25: ธุรกิจ ร้านค้า & ระบบองค์กร | C25: KP CRM | D25: ระบบจัดการรถเช่า ปรับปรุงจากการใช้งานจริงของร้านกว่า 30 ร้าน | E25: Kkd Khathawut | F25: https://www.kpcrm.net/ | H25: 9 | I25: ใช้ได้ | J25: เปิดคอมเมนต์
A26: 21 | B26: ธุรกิจ ร้านค้า & ระบบองค์กร | C26: UniJob Connect | D26: แพลตฟอร์มจับคู่งานด้วย AI เชื่อมบริษัท/SME กับนักศึกษา เน้นงานสาย Hard Skills ที่ตรงกับสายการเรียน | E26: New Saharat | F26: https://unijobconnect.com | H26: 8 | I26: ใช้ได้ | J26: เปิดคอมเมนต์
A27: 22 | B27: ธุรกิจ ร้านค้า & ระบบองค์กร | C27: คาร์แคร์จัดให้ | D27: ระบบบริหารจัดการร้านคาร์แคร์ ใช้ทั้งในร้านตัวเองและเปิดให้ตลาดใช้ | E27: Rattanin Trimaneepong | F27: https://carcarejadhai.com/pricing | H27: 6 | I27: ใช้ได้ | J27: เปิดคอมเมนต์
A28: 23 | B28: ธุรกิจ ร้านค้า & ระบบองค์กร | C28: CafePOS | D28: แอป POS บน iOS สำหรับร้านคาเฟ่และร้านอาหารขนาดเล็ก สั่งผ่าน QR ใช้ offline ได้ เชื่อมเครื่องพิมพ์ใบเสร็จ ระบบคิว พนักงาน และพร้อมเพย์ | E28: Korranat Naruenatthanaset | F28: https://apps.apple.com/app/id6761293829 | H28: 5 | I28: ใช้ได้ | J28: เปิดคอมเมนต์
A29: 24 | B29: ธุรกิจ ร้านค้า & ระบบองค์กร | C29: รวยจัด (RuayJud) | D29: ระบบจดรายรับ-รายจ่ายสำหรับร้านอาหาร แจ้งเตือนราคาวัตถุดิบขึ้น-ลง คำนวณต้นทุนต่อจานและต่อสูตร ใช้ผ่าน LINE | E29: Supakit Tuptimthong | F29: https://www.ruayjud.com/ | H29: 5 | I29: ใช้ได้ | J29: เปิดคอมเมนต์
A30: 25 | B30: ธุรกิจ ร้านค้า & ระบบองค์กร | C30: ระบบร้านอาหารครบวงจร (Chanin Pitiwong) | D30: เมนู QR code สำหรับพนักงานและห้องครัว ระบบจดรายจ่าย และจดสต็อก | E30: Chanin Pitiwong | F30: https://fastwork.co/.../ninja.../qr-code-design-53134308 | H30: 4 | I30: ลิงก์ถูก Facebook ตัด — ต้องค้นหาเอง | J30: เปิดคอมเมนต์
A31: 26 | B31: ธุรกิจ ร้านค้า & ระบบองค์กร | C31: NBIQ | D31: เว็บแอปช่วยงานตัวแทนประกัน (เริ่มที่ AIA ก่อน) ตั้งแต่การนำเข้าข้อมูล พัฒนาโดยทีม 2 คน + Claude | E31: Sirapob Boss Catteeyothai | F31: https://nbi-q.com/codev?src=Boss | H31: 3 | I31: ใช้ได้ | J31: เปิดคอมเมนต์
A32: 27 | B32: ธุรกิจ ร้านค้า & ระบบองค์กร | C32: Pixels Studio | D32: Web app คำนวณการใช้ไฟจาก Solar cell ออกแบบ plan และคำนวณการใช้ memory ของ CCTV | E32: Thanabadin Aussawatmeta | F32: https://pixels-studiodemo.netlify.app/ | H32: 3 | I32: ใช้ได้ | J32: เปิดคอมเมนต์
... A36: 31 | B36: ธุรกิจ ร้านค้า & ระบบองค์กร | C36: ระบบจัดการร้านค้าครบวงจร (New Saharat) | D36: ระบบดึงข้อมูลออเดอร์อัตโนมัติเมื่อปิดการขายผ่านแชท สรุปยอดขายรายเดือน/รายปี พร้อมติดตามสถานะจัดส่ง | E36: New Saharat | F36: https://www.facebook.com/yinzhangwenfang | H36: 2 | I36: ใช้ได้ | J36: เปิดคอมเมนต์
A37: 32 | B37: ธุรกิจ ร้านค้า & ระบบองค์กร | C37: TechGear | D37: ระบบลงทะเบียนและเช็คอินงานประชุม/Event/Exhibition รองรับ QR, NFC, สแกนใบหน้า, Payment Gateway, โค้ดส่วนลด และ Early Bird | E37: Gear Ceramics | F37: https://techgear.asia | G37: https://techgear.asia/interprex https://techgear.asia/photo | H37: 0 | I37: ใช้ได้ | J37: เปิดคอมเมนต์
A38: 33 | B38: สุขภาพ การแพทย์ & กีฬา | C38: MeeDeeThai | D38: เว็บคำนวณและแปลผลตรวจสุขภาพ | E38: Apiwat Augkaros | F38: https://medeethai.com/ | H38: 147 | I38: ใช้ได้ | J38: เปิดคอมเมนต์
A39: 34 | B39: สุขภาพ การแพทย์ & กีฬา | C39: Solfeggio Soundscape | D39: แอปฟังความถี่ Solfeggio เพื่อพักจิตใจ ปรับได้ 1-22,000 Hz ตั้งเวลาและบันทึกค่าที่ชอบได้ | E39: Siriphong Pakaratsakun | F39: https://drive.google.com/.../1bnGYrhSGol0qKYFI92gv4SDZJkI | H39: 52 | I39: ลิงก์ถูก Facebook ตัด — ต้องค้นหาเอง | J39: เปิดคอมเมนต์
A40: 35 | B40: สุขภาพ การแพทย์ & กีฬา | C40: Dog Bite Me | D40: เว็บประเมินความเสี่ยงจากหมากัด และคำนวณว่าต้องรับวัคซีนกี่เข็ม | E40: Jab Kluay | F40: https://dog-bite-me.vercel.app/ | H40: 17 | I40: ใช้ได้ | J40: เปิดคอมเมนต์
A41: 36 | B41: สุขภาพ การแพทย์ & กีฬา | C41: Punn Baby Pumping | D41: แอปติดตามการปั๊มนมและดูแลทารก ทำคนเดียว 100% | E41: Teerat Pipitcharulerd | F41: https://apps.apple.com/app/id6762541359 | G41: https://play.google.com/store/apps/details | H41: 15 | I41: ใช้ได้ | J41: เปิดคอมเมนต์
A42: 37 | B42: สุขภาพ การแพทย์ & กีฬา | C42: BetaScan | D42: แอปวิเคราะห์ว่าผาจำลองแต่ละเส้นทางปีนอย่างไร สร้างโมเดล ML ขึ้นมาเอง | E42: Warat Wongmaneekit | F42: https://betascan.app/ | H42: 7 | I42: ใช้ได้ | J42: เปิดคอมเมนต์
A43: 38 | B43: สุขภาพ การแพทย์ & กีฬา | C43: GlowPace | D43: แอปสำหรับคนทำ skin cycling เตือนว่าวันไหนต้องทาสกินแคร์ตัวใด | E43: DJdai Yodsapon | F43: https://glowpace.netlify.app/ | H43: 6 | I43: ใช้ได้ | J43: เปิดคอมเมนต์
A44: 39 | B44: สุขภาพ การแพทย์ & กีฬา | C44: JaiFlow | D44: แอปติดตามอารมณ์ มีระบบเกมช่วยให้บันทึกอารมณ์ทุกวันสนุกขึ้น สร้างเกาะและเก็บสตรีค | E44: Sorrawich Yooboon | F44: https://www.jaiflow.app/ | H44: 6 | I44: ใช้ได้ | J44: เปิดคอมเมนต์
...

Sheet สรุปตามหมวดหมู่
A1: จำนวนผลงานแยกตามหมวดหมู่
A3: หมวดหมู่ | B3: จำนวนผลงาน | C3: สัดส่วน | D3: รีแอ็กชันรวม
A4: AI Agent & Developer Tools | B4: =COUNTIF('แคตตาล็อกผลงาน'!$B$6:$B$152,$A4) | C4: =IFERROR(B4/$B$20,0) | D4: =SUMIF('แคตตาล็อกผลงาน'!$B$6:$B$152,$A4,'แคตตาล็อกผลงาน'!$H$6:$H$152)
A5: Productivity & เครื่องมือทำงาน | B5: =COUNTIF('แคตตาล็อกผลงาน'!$B$6:$B$152,$A5) | C5: =IFERROR(B5/$B$20,0) | D5: =SUMIF('แคตตาล็อกผลงาน'!$B$6:$B$152,$A5,'แคตตาล็อกผลงาน'!$H$6:$H$152)
A6: กฎหมาย & สิทธิ | B6: =COUNTIF('แคตตาล็อกผลงาน'!$B$6:$B$152,$A6) | C6: =IFERROR(B6/$B$20,0) | D6: =SUMIF('แคตตาล็อกผลงาน'!$B$6:$B$152,$A6,'แคตตาล็อกผลงาน'!$H$6:$H$152)
A7: การศึกษา & ภาษา | B7: =COUNTIF('แคตตาล็อกผลงาน'!$B$6:$B$152,$A7) | C7: =IFERROR(B7/$B$20,0) | D7: =SUMIF('แคตตาล็อกผลงาน'!$B$6:$B$152,$A7,'แคตตาล็อกผลงาน'!$H$6:$H$152)
A8: การเงิน & บัญชี | B8: =COUNTIF('แคตตาล็อกผลงาน'!$B$6:$B$152,$A8) | C8: =IFERROR(B8/$B$20,0) | D8: =SUMIF('แคตตาล็อกผลงาน'!$B$6:$B$152,$A8,'แคตตาล็อกผลงาน'!$H$6:$H$152)
A9: ช้อปปิ้ง & การตลาด | B9: =COUNTIF('แคตตาล็อกผลงาน'!$B$6:$B$152,$A9) | C9: =IFERROR(B9/$B$20,0) | D9: =SUMIF('แคตตาล็อกผลงาน'!$B$6:$B$152,$A9,'แคตตาล็อกผลงาน'!$H$6:$H$152)
A10: ท่องเที่ยว แผนที่ & ยานยนต์ | B10: =COUNTIF('แคตตาล็อกผลงาน'!$B$6:$B$152,$A10) | C10: =IFERROR(B10/$B$20,0) | D10: =SUMIF('แคตตาล็อกผลงาน'!$B$6:$B$152,$A10,'แคตตาล็อกผลงาน'!$H$6:$H$152)
A11: ธุรกิจ ร้านค้า & ระบบองค์กร | B11: =COUNTIF('แคตตาล็อกผลงาน'!$B$6:$B$152,$A11) | C11: =IFERROR(B11/$B$20,0) | D11: =SUMIF('แคตตาล็อกผลงาน'!$B$6:$B$152,$A11,'แคตตาล็อกผลงาน'!$H$6:$H$152)
A12: ภัยพิบัติ ภาครัฐ & GIS | B12: =COUNTIF('แคตตาล็อกผลงาน'!$B$6:$B$152,$A12) | C12: =IFERROR(B12/$B$20,0) | D12: =SUMIF('แคตตาล็อกผลงาน'!$B$6:$B$152,$A12,'แคตตาล็อกผลงาน'!$H$6:$H$152)
A13: รวมผลงาน & อื่น ๆ | B13: =COUNTIF('แคตตาล็อกผลงาน'!$B$6:$B$152,$A13) | C13: =IFERROR(B13/$B$20,0) | D13: =SUMIF('แคตตาล็อกผลงาน'!$B$6:$B$152,$A13,'แคตตาล็อกผลงาน'!$H$6:$H$152)
A14: สัตว์เลี้ยง | B14: =COUNTIF('แคตตาล็อกผลงาน'!$B$6:$B$152,$A14) | C14: =IFERROR(B14/$B$20,0) | D14: =SUMIF('แคตตาล็อกผลงาน'!$B$6:$B$152,$A14,'แคตตาล็อกผลงาน'!$H$6:$H$152)
A15: สื่อ คอนเทนต์ & ครีเอทีฟ | B15: =COUNTIF('แคตตาล็อกผลงาน'!$B$6:$B$152,$A15) | C15: =IFERROR(B15/$B$20,0) | D15: =SUMIF('แคตตาล็อกผลงาน'!$B$6:$B$152,$A15,'แคตตาล็อกผลงาน'!$H$6:$H$152)
... A19: ไลฟ์สไตล์ ครอบครัว & ชุมชน | B19: =COUNTIF('แคตตาล็อกผลงาน'!$B$6:$B$152,$A19) | C19: =IFERROR(B19/$B$20,0) | D19: =SUMIF('แคตตาล็อกผลงาน'!$B$6:$B$152,$A19,'แคตตาล็อกผลงาน'!$H$6:$H$152)
A20: รวมทั้งหมด | B20: =SUM(B4:B19) | C20: =IFERROR(B20/$B$20,0) | D20: =SUM(D4:D19)
A22: ตัวเลขทั้งหมดคำนวณด้วยสูตรจากชีต "แคตตาล็อกผลงาน" — แก้ข้อมูลในชีตนั้นแล้วตารางนี้อัปเดตเอง

Sheet วิธีทำและข้อจำกัด
A1: ที่มาของข้อมูล
A2: โพสต์ต้นทาง | B2: https://www.facebook.com/groups/1745892855948687/posts/2323047211566579/
A3: วิธีเก็บข้อมูล | B3: ดึงคอมเมนต์จาก DOM ของหน้าโพสต์ด้วยสคริปต์ tools/fb-comment-extractor.js รันใน DevTools Console ของเบราว์เซอร์ที่ล็อกอิน Facebook (Facebook ปิด Groups API สำหรับอ่านคอมเมนต์ตั้งแต่ปี 2020 จึงเรียกผ่าน API ไม่ได้)
A4: จำนวนไฟล์ที่นำมารวม | B4: ผลการรัน 3 ครั้ง (470 / 859 / 1,339 รายการ) นำมารวมและตัดซ้ำด้วย commentId เมื่อคอมเมนต์เดียวกันปรากฏหลายครั้ง เลือกเวอร์ชันที่ข้อความยาวที่สุด
A5: คอมเมนต์หลังตัดซ้ำ | B5: 1,329 คอมเมนต์ (คอมเมนต์หลัก 243 + ตอบกลับ 1,086)
A6: เกณฑ์คัดเข้าแคตตาล็อก | B6: คอมเมนต์ที่เจ้าของนำเสนอผลงานของตัวเองพร้อมลิงก์ รวมคอมเมนต์หลัก คอมเมนต์ที่เจ้าของตอบเสริมของตัวเอง และผลงาน 3 ชิ้นที่ปรากฏเฉพาะในคอมเมนต์ตอบกลับคนอื่น
A7: การรวมและการแยกรายการ | B7: คอมเมนต์หลักกับคอมเมนต์เสริมของเจ้าของคนเดียวกันถูกยุบเป็นผลงานเดียว ส่วนคอมเมนต์ที่นำเสนอผลงานหลายชิ้นที่ทำคนละเรื่อง ถูกแยกเป็นคนละรายการ
A8: จำนวนผลงานสุดท้าย | B8: 147 รายการ
A10: ข้อจำกัดที่ต้องรู้
A11: ลิงก์ที่ใช้ไม่ได้ | B11: 9 จาก 147 รายการ — Facebook ตัดข้อความลิงก์ยาวด้วย "..." และสคริปต์เก็บได้เฉพาะข้อความที่แสดง ไม่ได้เก็บ href จริงของแท็กลิงก์ ลิงก์ App Store กู้คืนได้จากเลข app id แต่ Play Store และ Chrome Web Store กู้ไม่ได้ รายการเหล่านี้ทำเครื่องหมายไว้ในคอลัมน์ "สถานะลิงก์"
A12: ยอดรีแอ็กชัน | B12: เป็นค่า ณ เวลาที่ดึงข้อมูล ไม่ใช่ค่าปัจจุบัน และคอมเมนต์ที่ไม่มีรีแอ็กชันบันทึกเป็น 0
A13: ความครบถ้วน | B13: คอมเมนต์ที่ Facebook ซ่อนหรือกรองเป็นสแปมจะไม่อยู่ใน DOM จึงไม่ถูกเก็บ ผลงานบางชิ้นอาจตกหล่นถ้าเจ้าของโพสต์ไว้ในคอมเมนต์ที่ถูกซ่อน
A14: หมวดหมู่ | B14: จัดด้วยการอ่านคำอธิบายของเจ้าของผลงานทีละรายการ ไม่ได้ใช้คีย์เวิร์ดอัตโนมัติ ผลงานที่คร่อมหลายหมวดถูกจัดตามการใช้งานหลักที่เจ้าของเน้น
A15: รายละเอียดผลงาน | B15: สรุปจากข้อความที่เจ้าของเขียนเท่านั้น ไม่ได้เข้าไปตรวจสอบเว็บหรือแอปจริง เพราะสภาพแวดล้อมที่ประมวลผลไม่มีสิทธิ์ออกอินเทอร์เน็ต
A16: ผลงานที่ไม่ระบุรายละเอียด | B16: บางรายการเจ้าของแนบแต่ลิงก์โดยไม่อธิบาย จัดไว้ในหมวด "รวมผลงาน & อื่น ๆ" และระบุไว้ในช่องรายละเอียดตามจริง
A18: รายการที่ลิงก์ใช้ไม่ได้
A19: ลำดับ 5 | B19: แอปจดรายรับรายจ่าย (Trancient Circuit) — https://play.google.com/store/apps/details
A20: ลำดับ 25 | B20: ระบบร้านอาหารครบวงจร (Chanin Pitiwong) — https://fastwork.co/.../ninja.../qr-code-design-53134308
A21: ลำดับ 34 | B21: Solfeggio Soundscape — https://drive.google.com/.../1bnGYrhSGol0qKYFI92gv4SDZJkI
A22: ลำดับ 54 | B22: Future Workforce English — https://futureworkforce.ajbankenglishkickstart.workers.de
A23: ลำดับ 89 | B23: แอปแชร์ลิงก์ผ่าน NFC (Warat Wongmaneekit) — https://play.google.com/store/apps/details
A24: ลำดับ 92 | B24: Speakit วาจา — https://play.google.com/store/apps/details
A25: ลำดับ 119 | B25: Chrome Extension เช็คคนไม่ฟอลบน X — https://chromewebstore.google.com/.../mljjpagc.../preview
A26: ลำดับ 120 | B26: S-Water — https://play.google.com/store/apps/details
A27: ลำดับ 122 | B27: Extension โพสต์กลุ่ม Facebook อัตโนมัติ — https://chromewebstore.google.com/.../nipfigapikmcbahblde
